<?xml version="1.0" ?>
<!-- =================================================================================== -->
<!-- |    This document was autogenerated by xacro from src/smartcar_simulation/urdf/smartcar.urdf.xacro | -->
<!-- |    EDITING THIS FILE BY HAND IS NOT RECOMMENDED                                 | -->
<!-- =================================================================================== -->
<robot name="smartcar">
  <material name="wheel_material">
    <color rgba="0 0 0 1"/>
  </material>
  <material name="imu_material">
    <color rgba="1 1 0 1"/>
  </material>
  <material name="lidar_material">
    <color rgba="0 0 0 1"/>
  </material>
  <material name="footprint_material">
    <color rgba="0 1 1 0.1"/>
  </material>
  <link name="base_link">
    <origin rpy="0 0 0" xyz="0 0 0"/>
  </link>
  <joint name="base_to_chassis" type="fixed">
    <parent link="base_link"/>
    <child link="chassis_link"/>
  </joint>
  <link name="chassis_link">
    <visual>
      <geometry>
        <box size="0.257 0.17 0.0125"/>
      </geometry>
      <origin rpy="0 0 0" xyz="0 0 0.032"/>
    </visual>
  </link>
  <link name="base_footprint">
    <visual>
      <geometry>
        <box size="0.514 0.34 0.128"/>
      </geometry>
      <material name="footprint_material"/>
      <origin rpy="0 0 0" xyz="0 0 0.064"/>
    </visual>
  </link>
  <joint name="base_to_footprint" type="fixed">
    <parent link="base_link"/>
    <child link="base_footprint"/>
  </joint>
  <joint name="front_left_wheel_steer_joint" type="revolute">
    <origin rpy="0 0 0" xyz="0.1285 0.085 0.032"/>
    <parent link="base_link"/>
    <child link="front_left_wheel_steer_link"/>
    <axis xyz="0 0 1"/>
    <limit effort="10" lower="-0.7853981633974483" upper="0.7853981633974483" velocity="1"/>
  </joint>
  <link name="front_left_wheel_steer_link">
    <origin rpy="0 0 0" xyz="0 0 0"/>
  </link>
  <joint name="front_left_wheel_joint" type="continuous">
    <origin rpy="0 0 0" xyz="0 0 0"/>
    <parent link="front_left_wheel_steer_link"/>
    <child link="front_left_wheel_link"/>
    <axis xyz="0 1 0"/>
  </joint>
  <link name="front_left_wheel_link">
    <visual>
      <geometry>
        <cylinder length="0.025" radius="0.032"/>
      </geometry>
      <origin rpy="1.5707963267948966 0 0" xyz="0 0.0125 0"/>
      <material name="wheel_material"/>
    </visual>
  </link>
  <joint name="front_right_wheel_steer_joint" type="revolute">
    <origin rpy="0 0 0" xyz="0.1285 -0.085 0.032"/>
    <parent link="base_link"/>
    <child link="front_right_wheel_steer_link"/>
    <axis xyz="0 0 1"/>
    <limit effort="10" lower="-0.7853981633974483" upper="0.7853981633974483" velocity="1"/>
  </joint>
  <link name="front_right_wheel_steer_link">
    <origin rpy="0 0 0" xyz="0 0 0"/>
  </link>
  <joint name="front_right_wheel_joint" type="continuous">
    <origin rpy="0 0 0" xyz="0 0 0"/>
    <parent link="front_right_wheel_steer_link"/>
    <child link="front_right_wheel_link"/>
    <axis xyz="0 1 0"/>
  </joint>
  <link name="front_right_wheel_link">
    <visual>
      <geometry>
        <cylinder length="0.025" radius="0.032"/>
      </geometry>
      <origin rpy="1.5707963267948966 0 0" xyz="0 -0.0125 0"/>
      <material name="wheel_material"/>
    </visual>
  </link>
  <joint name="rear_left_wheel_joint" type="continuous">
    <origin rpy="0 0 0" xyz="-0.1285 0.085 0.032"/>
    <parent link="base_link"/>
    <child link="rear_left_wheel_link"/>
    <axis xyz="0 1 0"/>
  </joint>
  <link name="rear_left_wheel_link">
    <visual>
      <geometry>
        <cylinder length="0.025" radius="0.032"/>
      </geometry>
      <origin rpy="1.5707963267948966 0 0" xyz="0 0.0125 0"/>
      <material name="wheel_material"/>
    </visual>
  </link>
  <joint name="rear_right_wheel_joint" type="continuous">
    <origin rpy="0 0 0" xyz="-0.1285 -0.085 0.032"/>
    <parent link="base_link"/>
    <child link="rear_right_wheel_link"/>
    <axis xyz="0 1 0"/>
  </joint>
  <link name="rear_right_wheel_link">
    <visual>
      <geometry>
        <cylinder length="0.025" radius="0.032"/>
      </geometry>
      <origin rpy="1.5707963267948966 0 0" xyz="0 -0.0125 0"/>
      <material name="wheel_material"/>
    </visual>
  </link>
  <link name="imu_link">
    <visual>
      <origin rpy="0 0 0" xyz="0.1285 0 0.064"/>
      <geometry>
        <box size="0.01 0.01 0.01"/>
      </geometry>
      <material name="imu_material"/>
    </visual>
    <sensor name="my_imu" type="imu">
      <always_on>true</always_on>
      <update_rate>30</update_rate>
      <plugin filename="libgazebo_ros_imu_sensor.so" name="my_imu_plugin">
        <ros>
          <!-- Will publish to /imu_data -->
          <namespace/>
          <remapping>~/out:=imu_data</remapping>
        </ros>
      </plugin>
    </sensor>
  </link>
  <joint name="base_to_imu" type="fixed">
    <parent link="base_link"/>
    <child link="imu_link"/>
  </joint>
  <link name="sllidar_base_link">
    <visual>
      <origin rpy="0 0 0" xyz="0.1285 0 0.096"/>
      <geometry>
        <cylinder length="0.025" radius="0.025"/>
      </geometry>
      <material name="lidar_material"/>
    </visual>
    <sensor name="lidar" type="gpu_ray">
      <ray>
        <scan>
          <horizontal>
            <samples>720</samples>
            <resolution>1</resolution>
            <min_angle>-1.5707963267948966</min_angle>
            <max_angle>1.5707963267948966</max_angle>
          </horizontal>
        </scan>
        <range>
          <min>0.10</min>
          <max>30.0</max>
          <resolution>0.01</resolution>
        </range>
        <!-- Using gazebo's noise instead of plugin's -->
        <noise>
          <type>gaussian</type>
          <mean>0.0</mean>
          <stddev>0.01</stddev>
        </noise>
      </ray>
      <!-- Using gazebo's update rate instead of plugin's -->
      <update_rate>30</update_rate>
      <plugin filename="libgazebo_ros_ray_sensor.so" name="my_lidar">
        <!-- Change namespace and output topic so published topic is /rrbot/laser/scan -->
        <ros>
          <namespace>/rrbot/laser</namespace>
          <remapping>~/out:=scan</remapping>
        </ros>
        <!-- Set output to sensor_msgs/LaserScan to get same output type as gazebo_ros_laser -->
        <output_type>sensor_msgs/LaserScan</output_type>
        <!-- <frame_name> ommited, will default to hokuo_link -->
      </plugin>
    </sensor>
  </link>
  <joint name="base_to_lidar" type="fixed">
    <parent link="base_link"/>
    <child link="sllidar_base_link"/>
  </joint>
</robot>
